Workbook

Sheet General Information
A1: BOSE QuietComfort | C1: Group 2
A4: DETAILED INFORMATION
A6: Goal of Forecasting
A23: Reference Planning Period
A36: Trend and Seasonality
A50: Forecast
A75: Supply Plan
A85: Inventory Management

Sheet Raw Black and outliers handling
A1: Black QC Headphones: Raw Data and Outliers Handling
B3: Date | C3: Date Cleaned | D3: Orders | F3: Date | G3: Combined Daily order | H3: Quarters | I3: Moving Average on Months | J3: Lower Bound Computed on Moving Average | K3: Upper Bound Computed on Moving Average | L3: Presumed Outliers | M3: Period for moving average | N3: Lower Bound Computed on the whole series of data | O3: Upper Bound Computed on the whole series of data | Q3: Bose Quiet Comfort Black
B4: 45562.73 | C4: =INT(B4) -> 45562 | D4: 13614 | F4: 45562 | G4: =SUMIF(C:C, F4, D:D) -> 25910 | H4: =ROUNDUP(MONTH(Table3[[#This Row],[Date]])/3, 0) -> 3 | L4: #N/A | M4: 22 | N4: =$V$46 -> 45729.883 | O4: =$U$46 -> 5411.2257
B5: 45562.342 | C5: =INT(B5) -> 45562 | D5: 12296 | F5: =WORKDAY(F4,-1) -> 45561 | G5: =SUMIF(C:C, F5, D:D) -> 36491 | H5: =ROUNDUP(MONTH(Table3[[#This Row],[Date]])/3, 0) -> 3 | L5: =Table3[[#This Row],[Combined Daily order]] -> 36491 | N5: =$V$46 -> 45729.883 | O5: =$U$46 -> 5411.2257
B6: 45561.927 | C6: =INT(B6) -> 45561 | D6: 13540 | F6: =WORKDAY(F5,-1) -> 45560 | G6: =SUMIF(C:C, F6, D:D) -> 26068 | H6: =ROUNDUP(MONTH(Table3[[#This Row],[Date]])/3, 0) -> 3 | L6: #N/A | N6: =$V$46 -> 45729.883 | O6: =$U$46 -> 5411.2257
B7: 45561.508 | C7: =INT(B7) -> 45561 | D7: 11675 | F7: =WORKDAY(F6,-1) -> 45559 | G7: =SUMIF(C:C, F7, D:D) -> 40865 | H7: =ROUNDUP(MONTH(Table3[[#This Row],[Date]])/3, 0) -> 3 | L7: =Table3[[#This Row],[Combined Daily order]] -> 40865 | N7: =$V$46 -> 45729.883 | O7: =$U$46 -> 5411.2257
B8: 45561.088 | C8: =INT(B8) -> 45561 | D8: 11276 | F8: =WORKDAY(F7,-1) -> 45558 | G8: =SUMIF(C:C, F8, D:D) -> 27032 | H8: =ROUNDUP(MONTH(Table3[[#This Row],[Date]])/3, 0) -> 3 | L8: #N/A | N8: =$V$46 -> 45729.883 | O8: =$U$46 -> 5411.2257
B9: 45560.712 | C9: =INT(B9) -> 45560 | D9: 12662 | F9: =WORKDAY(F8,-1) -> 45555 | G9: =SUMIF(C:C, F9, D:D) -> 25465 | H9: =ROUNDUP(MONTH(Table3[[#This Row],[Date]])/3, 0) -> 3 | L9: #N/A | N9: =$V$46 -> 45729.883 | O9: =$U$46 -> 5411.2257
B10: 45560.315 | C10: =INT(B10) -> 45560 | D10: 13406 | F10: =WORKDAY(F9,-1) -> 45554 | G10: =SUMIF(C:C, F10, D:D) -> 36114 | H10: =ROUNDUP(MONTH(Table3[[#This Row],[Date]])/3, 0) -> 3 | L10: =Table3[[#This Row],[Combined Daily order]] -> 36114 | N10: =$V$46 -> 45729.883 | O10: =$U$46 -> 5411.2257
B11: 45559.924 | C11: =INT(B11) -> 45559 | D11: 14628 | F11: =WORKDAY(F10,-1) -> 45553 | G11: =SUMIF(C:C, F11, D:D) -> 25049 | H11: =ROUNDUP(MONTH(Table3[[#This Row],[Date]])/3, 0) -> 3 | L11: #N/A | N11: =$V$46 -> 45729.883 | O11: =$U$46 -> 5411.2257
B12: 45559.553 | C12: =INT(B12) -> 45559 | D12: 12678 | F12: =WORKDAY(F11,-1) -> 45552 | G12: =SUMIF(C:C, F12, D:D) -> 36767 | H12: =ROUNDUP(MONTH(Table3[[#This Row],[Date]])/3, 0) -> 3 | L12: =Table3[[#This Row],[Combined Daily order]] -> 36767 | N12: =$V$46 -> 45729.883 | O12: =$U$46 -> 5411.2257
B13: 45559.149 | C13: =INT(B13) -> 45559 | D13: 13559 | F13: =WORKDAY(F12,-1) -> 45551 | G13: =SUMIF(C:C, F13, D:D) -> 27301 | H13: =ROUNDUP(MONTH(Table3[[#This Row],[Date]])/3, 0) -> 3 | L13: #N/A | N13: =$V$46 -> 45729.883 | O13: =$U$46 -> 5411.2257
B14: 45558.735 | C14: =INT(B14) -> 45558 | D14: 13248 | F14: =WORKDAY(F13,-1) -> 45548 | G14: =SUMIF(C:C, F14, D:D) -> 35320 | H14: =ROUNDUP(MONTH(Table3[[#This Row],[Date]])/3, 0) -> 3 | L14: #N/A | N14: =$V$46 -> 45729.883 | O14: =$U$46 -> 5411.2257
B15: 45558.346 | C15: =INT(B15) -> 45558 | D15: 13784 | F15: =WORKDAY(F14,-1) -> 45547 | G15: =SUMIF(C:C, F15, D:D) -> 25240 | H15: =ROUNDUP(MONTH(Table3[[#This Row],[Date]])/3, 0) -> 3 | I15: {=(SUM(OFFSET(G15, -$M$4/2+1, 0, $M$4-1, 1)) + (INDIRECT("G" & ROW(G15) - $M$4/2) + INDIRECT("G" & ROW(G15) + $M$4/2))/2) / $M$4} -> 31088.341 | J15: =Table3[[#This Row],[Moving Average on Months]] - 1.96*STDEV(OFFSET(Table3[[#This Row],[Combined Daily order]], -$M$4/2, 0, $M$4+1, 1)) -> 17937.05 | K15: =Table3[[#This Row],[Moving Average on Months]] + 1.96*STDEV(OFFSET(Table3[[#This Row],[Combined Daily order]], -$M$4/2, 0, $M$4+1, 1)) -> 44239.632 | L15: #N/A | N15: =$V$46 -> 45729.883 | O15: =$U$46 -> 5411.2257
B16: 45555.654 | C16: =INT(B16) -> 45555 | D16: 12449 | F16: =WORKDAY(F15,-1) -> 45546 | G16: =SUMIF(C:C, F16, D:D) -> 39060 | H16: =ROUNDUP(MONTH(Table3[[#This Row],[Date]])/3, 0) -> 3 | I16: {=(SUM(OFFSET(G16, -$M$4/2+1, 0, $M$4-1, 1)) + (INDIRECT("G" & ROW(G16) - $M$4/2) + INDIRECT("G" & ROW(G16) + $M$4/2))/2) / $M$4} -> 30999.636 | J16: =Table3[[#This Row],[Moving Average on Months]] - 1.96*STDEV(OFFSET(Table3[[#This Row],[Combined Daily order]], -$M$4/2, 0, $M$4+1, 1)) -> 17844.926 | K16: =Table3[[#This Row],[Moving Average on Months]] + 1.96*STDEV(OFFSET(Table3[[#This Row],[Combined Daily order]], -$M$4/2, 0, $M$4+1, 1)) -> 44154.346 | L16: =Table3[[#This Row],[Combined Daily order]] -> 39060 | N16: =$V$46 -> 45729.883 | O16: =$U$46 -> 5411.2257
B17: 45555.224 | C17: =INT(B17) -> 45555 | D17: 13016 | F17: =WORKDAY(F16,-1) -> 45545 | G17: =SUMIF(C:C, F17, D:D) -> 24227 | H17: =ROUNDUP(MONTH(Table3[[#This Row],[Date]])/3, 0) -> 3 | I17: {=(SUM(OFFSET(G17, -$M$4/2+1, 0, $M$4-1, 1)) + (INDIRECT("G" & ROW(G17) - $M$4/2) + INDIRECT("G" & ROW(G17) + $M$4/2))/2) / $M$4} -> 30948.932 | J17: =Table3[[#This Row],[Moving Average on Months]] - 1.96*STDEV(OFFSET(Table3[[#This Row],[Combined Daily order]], -$M$4/2, 0, $M$4+1, 1)) -> 17691.219 | K17: =Table3[[#This Row],[Moving Average on Months]] + 1.96*STDEV(OFFSET(Table3[[#This Row],[Combined Daily order]], -$M$4/2, 0, $M$4+1, 1)) -> 44206.644 | L17: #N/A | N17: =$V$46 -> 45729.883 | O17: =$U$46 -> 5411.2257
B18: 45554.82 | C18: =INT(B18) -> 45554 | D18: 12256 | F18: =WORKDAY(F17,-1) -> 45544 | G18: =SUMIF(C:C, F18, D:D) -> 26751 | H18: =ROUNDUP(MONTH(Table3[[#This Row],[Date]])/3, 0) -> 3 | I18: {=(SUM(OFFSET(G18, -$M$4/2+1, 0, $M$4-1, 1)) + (INDIRECT("G" & ROW(G18) - $M$4/2) + INDIRECT("G" & ROW(G18) + $M$4/2))/2) / $M$4} -> 30737 | J18: =Table3[[#This Row],[Moving Average on Months]] - 1.96*STDEV(OFFSET(Table3[[#This Row],[Combined Daily order]], -$M$4/2, 0, $M$4+1, 1)) -> 17586.795 | K18: =Table3[[#This Row],[Moving Average on Months]] + 1.96*STDEV(OFFSET(Table3[[#This Row],[Combined Daily order]], -$M$4/2, 0, $M$4+1, 1)) -> 43887.205 | L18: #N/A | N18: =$V$46 -> 45729.883 | O18: =$U$46 -> 5411.2257
B19: 45554.406 | C19: =INT(B19) -> 45554 | D19: 11650 | F19: =WORKDAY(F18,-1) -> 45541 | G19: =SUMIF(C:C, F19, D:D) -> 42169 | H19: =ROUNDUP(MONTH(Table3[[#This Row],[Date]])/3, 0) -> 3 | I19: {=(SUM(OFFSET(G19, -$M$4/2+1, 0, $M$4-1, 1)) + (INDIRECT("G" & ROW(G19) - $M$4/2) + INDIRECT("G" & ROW(G19) + $M$4/2))/2) / $M$4} -> 30509 | J19: =Table3[[#This Row],[Moving Average on Months]] - 1.96*STDEV(OFFSET(Table3[[#This Row],[Combined Daily order]], -$M$4/2, 0, $M$4+1, 1)) -> 17800.096 | K19: =Table3[[#This Row],[Moving Average on Months]] + 1.96*STDEV(OFFSET(Table3[[#This Row],[Combined Daily order]], -$M$4/2, 0, $M$4+1, 1)) -> 43217.904 | L19: =Table3[[#This Row],[Combined Daily order]] -> 42169 | N19: =$V$46 -> 45729.883 | O19: =$U$46 -> 5411.2257
B20: 45554.012 | C20: =INT(B20) -> 45554 | D20: 12208 | F20: =WORKDAY(F19,-1) -> 45540 | G20: =SUMIF(C:C, F20, D:D) -> 24206 | H20: =ROUNDUP(MONTH(Table3[[#This Row],[Date]])/3, 0) -> 3 | I20: {=(SUM(OFFSET(G20, -$M$4/2+1, 0, $M$4-1, 1)) + (INDIRECT("G" & ROW(G20) - $M$4/2) + INDIRECT("G" & ROW(G20) + $M$4/2))/2) / $M$4} -> 30645.773 | J20: =Table3[[#This Row],[Moving Average on Months]] - 1.96*STDEV(OFFSET(Table3[[#This Row],[Combined Daily order]], -$M$4/2, 0, $M$4+1, 1)) -> 17926.703 | K20: =Table3[[#This Row],[Moving Average on Months]] + 1.96*STDEV(OFFSET(Table3[[#This Row],[Combined Daily order]], -$M$4/2, 0, $M$4+1, 1)) -> 43364.842 | L20: #N/A | N20: =$V$46 -> 45729.883 | O20: =$U$46 -> 5411.2257
B21: 45553.63 | C21: =INT(B21) -> 45553 | D21: 11847 | F21: =WORKDAY(F20,-1) -> 45539 | G21: =SUMIF(C:C, F21, D:D) -> 39550 | H21: =ROUNDUP(MONTH(Table3[[#This Row],[Date]])/3, 0) -> 3 | I21: {=(SUM(OFFSET(G21, -$M$4/2+1, 0, $M$4-1, 1)) + (INDIRECT("G" & ROW(G21) - $M$4/2) + INDIRECT("G" & ROW(G21) + $M$4/2))/2) / $M$4} -> 30566.091 | J21: =Table3[[#This Row],[Moving Average on Months]] - 1.96*STDEV(OFFSET(Table3[[#This Row],[Combined Daily order]], -$M$4/2, 0, $M$4+1, 1)) -> 17728.781 | K21: =Table3[[#This Row],[Moving Average on Months]] + 1.96*STDEV(OFFSET(Table3[[#This Row],[Combined Daily order]], -$M$4/2, 0, $M$4+1, 1)) -> 43403.401 | L21: =Table3[[#This Row],[Combined Daily order]] -> 39550 | N21: =$V$46 -> 45729.883 | O21: =$U$46 -> 5411.2257
B22: 45553.239 | C22: =INT(B22) -> 45553 | D22: 13202 | F22: =WORKDAY(F21,-1) -> 45538 | G22: =SUMIF(C:C, F22, D:D) -> 24805 | H22: =ROUNDUP(MONTH(Table3[[#This Row],[Date]])/3, 0) -> 3 | I22: {=(SUM(OFFSET(G22, -$M$4/2+1, 0, $M$4-1, 1)) + (INDIRECT("G" & ROW(G22) - $M$4/2) + INDIRECT("G" & ROW(G22) + $M$4/2))/2) / $M$4} -> 30450.273 | J22: =Table3[[#This Row],[Moving Average on Months]] - 1.96*STDEV(OFFSET(Table3[[#This Row],[Combined Daily order]], -$M$4/2, 0, $M$4+1, 1)) -> 17814.31 | K22: =Table3[[#This Row],[Moving Average on Months]] + 1.96*STDEV(OFFSET(Table3[[#This Row],[Combined Daily order]], -$M$4/2, 0, $M$4+1, 1)) -> 43086.235 | L22: #N/A | N22: =$V$46 -> 45729.883 | O22: =$U$46 -> 5411.2257
B23: 45552.866 | C23: =INT(B23) -> 45552 | D23: 11602 | F23: =WORKDAY(F22,-1) -> 45537 | G23: =SUMIF(C:C, F23, D:D) -> 38326 | H23: =ROUNDUP(MONTH(Table3[[#This Row],[Date]])/3, 0) -> 3 | I23: {=(SUM(OFFSET(G23, -$M$4/2+1, 0, $M$4-1, 1)) + (INDIRECT("G" & ROW(G23) - $M$4/2) + INDIRECT("G" & ROW(G23) + $M$4/2))/2) / $M$4} -> 30244.091 | J23: =Table3[[#This Row],[Moving Average on Months]] - 1.96*STDEV(OFFSET(Table3[[#This Row],[Combined Daily order]], -$M$4/2, 0, $M$4+1, 1)) -> 17166.305 | K23: =Table3[[#This Row],[Moving Average on Months]] + 1.96*STDEV(OFFSET(Table3[[#This Row],[Combined Daily order]], -$M$4/2, 0, $M$4+1, 1)) -> 43321.877 | L23: =Table3[[#This Row],[Combined Daily order]] -> 38326 | N23: =$V$46 -> 45729.883 | O23: =$U$46 -> 5411.2257
B24: 45552.473 | C24: =INT(B24) -> 45552 | D24: 12174 | F24: =WORKDAY(F23,-1) -> 45534 | G24: =SUMIF(C:C, F24, D:D) -> 23906 | H24: =ROUNDUP(MONTH(Table3[[#This Row],[Date]])/3, 0) -> 3 | I24: {=(SUM(OFFSET(G24, -$M$4/2+1, 0, $M$4-1, 1)) + (INDIRECT("G" & ROW(G24) - $M$4/2) + INDIRECT("G" & ROW(G24) + $M$4/2))/2) / $M$4} -> 30009.841 | J24: =Table3[[#This Row],[Moving Average on Months]] - 1.96*STDEV(OFFSET(Table3[[#This Row],[Combined Daily order]], -$M$4/2, 0, $M$4+1, 1)) -> 17171.087 | K24: =Table3[[#This Row],[Moving Average on Months]] + 1.96*STDEV(OFFSET(Table3[[#This Row],[Combined Daily order]], -$M$4/2, 0, $M$4+1, 1)) -> 42848.595 | L24: #N/A | N24: =$V$46 -> 45729.883 | O24: =$U$46 -> 5411.2257
B25: 45552.086 | C25: =INT(B25) -> 45552 | D25: 12991 | F25: =WORKDAY(F24,-1) -> 45533 | G25: =SUMIF(C:C, F25, D:D) -> 35106 | H25: =ROUNDUP(MONTH(Table3[[#This Row],[Date]])/3, 0) -> 3 | I25: {=(SUM(OFFSET(G25, -$M$4/2+1, 0, $M$4-1, 1)) + (INDIRECT("G" & ROW(G25) - $M$4/2) + INDIRECT("G" & ROW(G25) + $M$4/2))/2) / $M$4} -> 29833.114 | J25: =Table3[[#This Row],[Moving Average on Months]] - 1.96*STDEV(OFFSET(Table3[[#This Row],[Combined Daily order]], -$M$4/2, 0, $M$4+1, 1)) -> 16594.682 | K25: =Table3[[#This Row],[Moving Average on Months]] + 1.96*STDEV(OFFSET(Table3[[#This Row],[Combined Daily order]], -$M$4/2, 0, $M$4+1, 1)) -> 43071.545 | L25: #N/A | N25: =$V$46 -> 45729.883 | O25: =$U$46 -> 5411.2257
B26: 45551.666 | C26: =INT(B26) -> 45551 | D26: 13471 | F26: =WORKDAY(F25,-1) -> 45532 | G26: =SUMIF(C:C, F26, D:D) -> 22341 | H26: =ROUNDUP(MONTH(Table3[[#This Row],[Date]])/3, 0) -> 3 | I26: {=(SUM(OFFSET(G26, -$M$4/2+1, 0, $M$4-1, 1)) + (INDIRECT("G" & ROW(G26) - $M$4/2) + INDIRECT("G" & ROW(G26) + $M$4/2))/2) / $M$4} -> 29676.523 | J26: =Table3[[#This Row],[Moving Average on Months]] - 1.96*STDEV(OFFSET(Table3[[#This Row],[Combined Daily order]], -$M$4/2, 0, $M$4+1, 1)) -> 16614.859 | K26: =Table3[[#This Row],[Moving Average on Months]] + 1.96*STDEV(OFFSET(Table3[[#This Row],[Combined Daily order]], -$M$4/2, 0, $M$4+1, 1)) -> 42738.186 | L26: #N/A | N26: =$V$46 -> 45729.883 | O26: =$U$46 -> 5411.2257
B27: 45551.29 | C27: =INT(B27) -> 45551 | D27: 13830 | F27: =WORKDAY(F26,-1) -> 45531 | G27: =SUMIF(C:C, F27, D:D) -> 36157 | H27: =ROUNDUP(MONTH(Table3[[#This Row],[Date]])/3, 0) -> 3 | I27: {=(SUM(OFFSET(G27, -$M$4/2+1, 0, $M$4-1, 1)) + (INDIRECT("G" & ROW(G27) - $M$4/2) + INDIRECT("G" & ROW(G27) + $M$4/2))/2) / $M$4} -> 29394.318 | J27: =Table3[[#This Row],[Moving Average on Months]] - 1.96*STDEV(OFFSET(Table3[[#This Row],[Combined Daily order]], -$M$4/2, 0, $M$4+1, 1)) -> 15853.399 | K27: =Table3[[#This Row],[Moving Average on Months]] + 1.96*STDEV(OFFSET(Table3[[#This Row],[Combined Daily order]], -$M$4/2, 0, $M$4+1, 1)) -> 42935.237 | L27: =Table3[[#This Row],[Combined Daily order]] -> 36157 | N27: =$V$46 -> 45729.883 | O27: =$U$46 -> 5411.2257
B28: 45548.815 | C28: =INT(B28) -> 45548 | D28: 11982 | F28: =WORKDAY(F27,-1) -> 45530 | G28: =SUMIF(C:C, F28, D:D) -> 24171 | H28: =ROUNDUP(MONTH(Table3[[#This Row],[Date]])/3, 0) -> 3 | I28: {=(SUM(OFFSET(G28, -$M$4/2+1, 0, $M$4-1, 1)) + (INDIRECT("G" & ROW(G28) - $M$4/2) + INDIRECT("G" & ROW(G28) + $M$4/2))/2) / $M$4} -> 29161.795 | J28: =Table3[[#This Row],[Moving Average on Months]] - 1.96*STDEV(OFFSET(Table3[[#This Row],[Combined Daily order]], -$M$4/2, 0, $M$4+1, 1)) -> 16155.034 | K28: =Table3[[#This Row],[Moving Average on Months]] + 1.96*STDEV(OFFSET(Table3[[#This Row],[Combined Daily order]], -$M$4/2, 0, $M$4+1, 1)) -> 42168.557 | L28: #N/A | N28: =$V$46 -> 45729.883 | O28: =$U$46 -> 5411.2257
B29: 45548.404 | C29: =INT(B29) -> 45548 | D29: 11995 | F29: =WORKDAY(F28,-1) -> 45527 | G29: =SUMIF(C:C, F29, D:D) -> 33437 | H29: =ROUNDUP(MONTH(Table3[[#This Row],[Date]])/3, 0) -> 3 | I29: {=(SUM(OFFSET(G29, -$M$4/2+1, 0, $M$4-1, 1)) + (INDIRECT("G" & ROW(G29) - $M$4/2) + INDIRECT("G" & ROW(G29) + $M$4/2))/2) / $M$4} -> 29454.023 | J29: =Table3[[#This Row],[Moving Average on Months]] - 1.96*STDEV(OFFSET(Table3[[#This Row],[Combined Daily order]], -$M$4/2, 0, $M$4+1, 1)) -> 16605.449 | K29: =Table3[[#This Row],[Moving Average on Months]] + 1.96*STDEV(OFFSET(Table3[[#This Row],[Combined Daily order]], -$M$4/2, 0, $M$4+1, 1)) -> 42302.597 | L29: #N/A | N29: =$V$46 -> 45729.883 | O29: =$U$46 -> 5411.2257
B30: 45548.029 | C30: =INT(B30) -> 45548 | D30: 11343 | F30: =WORKDAY(F29,-1) -> 45526 | G30: =SUMIF(C:C, F30, D:D) -> 24428 | H30: =ROUNDUP(MONTH(Table3[[#This Row],[Date]])/3, 0) -> 3 | I30: {=(SUM(OFFSET(G30, -$M$4/2+1, 0, $M$4-1, 1)) + (INDIRECT("G" & ROW(G30) - $M$4/2) + INDIRECT("G" & ROW(G30) + $M$4/2))/2) / $M$4} -> 29023.841 | J30: =Table3[[#This Row],[Moving Average on Months]] - 1.96*STDEV(OFFSET(Table3[[#This Row],[Combined Daily order]], -$M$4/2, 0, $M$4+1, 1)) -> 15552.505 | K30: =Table3[[#This Row],[Moving Average on Months]] + 1.96*STDEV(OFFSET(Table3[[#This Row],[Combined Daily order]], -$M$4/2, 0, $M$4+1, 1)) -> 42495.177 | L30: #N/A | N30: =$V$46 -> 45729.883 | O30: =$U$46 -> 5411.2257
B31: 45547.613 | C31: =INT(B31) -> 45547 | D31: 11358 | F31: =WORKDAY(F30,-1) -> 45525 | G31: =SUMIF(C:C, F31, D:D) -> 34087 | H31: =ROUNDUP(MONTH(Table3[[#This Row],[Date]])/3, 0) -> 3 | I31: {=(SUM(OFFSET(G31, -$M$4/2+1, 0, $M$4-1, 1)) + (INDIRECT("G" & ROW(G31) - $M$4/2) + INDIRECT("G" & ROW(G31) + $M$4/2))/2) / $M$4} -> 28594.318 | J31: =Table3[[#This Row],[Moving Average on Months]] - 1.96*STDEV(OFFSET(Table3[[#This Row],[Combined Daily order]], -$M$4/2, 0, $M$4+1, 1)) -> 16334.784 | K31: =Table3[[#This Row],[Moving Average on Months]] + 1.96*STDEV(OFFSET(Table3[[#This Row],[Combined Daily order]], -$M$4/2, 0, $M$4+1, 1)) -> 40853.853 | L31: #N/A | N31: =$V$46 -> 45729.883 | O31: =$U$46 -> 5411.2257
B32: 45547.189 | C32: =INT(B32) -> 45547 | D32: 13882 | F32: =WORKDAY(F31,-1) -> 45524 | G32: =SUMIF(C:C, F32, D:D) -> 23986 | H32: =ROUNDUP(MONTH(Table3[[#This Row],[Date]])/3, 0) -> 3 | I32: {=(SUM(OFFSET(G32, -$M$4/2+1, 0, $M$4-1, 1)) + (INDIRECT("G" & ROW(G32) - $M$4/2) + INDIRECT("G" & ROW(G32) + $M$4/2))/2) / $M$4} -> 28238.023 | J32: =Table3[[#This Row],[Moving Average on Months]] - 1.96*STDEV(OFFSET(Table3[[#This Row],[Combined Daily order]], -$M$4/2, 0, $M$4+1, 1)) -> 15590.131 | K32: =Table3[[#This Row],[Moving Average on Months]] + 1.96*STDEV(OFFSET(Table3[[#This Row],[Combined Daily order]], -$M$4/2, 0, $M$4+1, 1)) -> 40885.914 | L32: #N/A | N32: =$V$46 -> 45729.883 | O32: =$U$46 -> 5411.2257
B33: 45546.774 | C33: =INT(B33) -> 45546 | D33: 14222 | F33: =WORKDAY(F32,-1) -> 45523 | G33: =SUMIF(C:C, F33, D:D) -> 32081 | H33: =ROUNDUP(MONTH(Table3[[#This Row],[Date]])/3, 0) -> 3 | I33: {=(SUM(OFFSET(G33, -$M$4/2+1, 0, $M$4-1, 1)) + (INDIRECT("G" & ROW(G33) - $M$4/2) + INDIRECT("G" & ROW(G33) + $M$4/2))/2) / $M$4} -> 27643.091 | J33: =Table3[[#This Row],[Moving Average on Months]] - 1.96*STDEV(OFFSET(Table3[[#This Row],[Combined Daily order]], -$M$4/2, 0, $M$4+1, 1)) -> 15320.659 | K33: =Table3[[#This Row],[Moving Average on Months]] + 1.96*STDEV(OFFSET(Table3[[#This Row],[Combined Daily order]], -$M$4/2, 0, $M$4+1, 1)) -> 39965.522 | L33: #N/A | N33: =$V$46 -> 45729.883 | O33: =$U$46 -> 5411.2257
B34: 45546.379 | C34: =INT(B34) -> 45546 | D34: 12161 | F34: =WORKDAY(F33,-1) -> 45520 | G34: =SUMIF(C:C, F34, D:D) -> 20663 | H34: =ROUNDUP(MONTH(Table3[[#This Row],[Date]])/3, 0) -> 3 | I34: {=(SUM(OFFSET(G34, -$M$4/2+1, 0, $M$4-1, 1)) + (INDIRECT("G" & ROW(G34) - $M$4/2) + INDIRECT("G" & ROW(G34) + $M$4/2))/2) / $M$4} -> 27235.591 | J34: =Table3[[#This Row],[Moving Average on Months]] - 1.96*STDEV(OFFSET(Table3[[#This Row],[Combined Daily order]], -$M$4/2, 0, $M$4+1, 1)) -> 14959.73 | K34: =Table3[[#This Row],[Moving Average on Months]] + 1.96*STDEV(OFFSET(Table3[[#This Row],[Combined Daily order]], -$M$4/2, 0, $M$4+1, 1)) -> 39511.451 | L34: #N/A | N34: =$V$46 -> 45729.883 | O34: =$U$46 -> 5411.2257
B35: 45546.002 | C35: =INT(B35) -> 45546 | D35: 12677 | F35: =WORKDAY(F34,-1) -> 45519 | G35: =SUMIF(C:C, F35, D:D) -> 33098 | H35: =ROUNDUP(MONTH(Table3[[#This Row],[Date]])/3, 0) -> 3 | I35: {=(SUM(OFFSET(G35, -$M$4/2+1, 0, $M$4-1, 1)) + (INDIRECT("G" & ROW(G35) - $M$4/2) + INDIRECT("G" & ROW(G35) + $M$4/2))/2) / $M$4} -> 26853.682 | J35: =Table3[[#This Row],[Moving Average on Months]] - 1.96*STDEV(OFFSET(Table3[[#This Row],[Combined Daily order]], -$M$4/2, 0, $M$4+1, 1)) -> 14977.885 | K35: =Table3[[#This Row],[Moving Average on Months]] + 1.96*STDEV(OFFSET(Table3[[#This Row],[Combined Daily order]], -$M$4/2, 0, $M$4+1, 1)) -> 38729.479 | L35: #N/A | N35: =$V$46 -> 45729.883 | O35: =$U$46 -> 5411.2257
B36: 45545.6 | C36: =INT(B36) -> 45545 | D36: 13017 | F36: =WORKDAY(F35,-1) -> 45518 | G36: =SUMIF(C:C, F36, D:D) -> 21747 | H36: =ROUNDUP(MONTH(Table3[[#This Row],[Date]])/3, 0) -> 3 | I36: {=(SUM(OFFSET(G36, -$M$4/2+1, 0, $M$4-1, 1)) + (INDIRECT("G" & ROW(G36) - $M$4/2) + INDIRECT("G" & ROW(G36) + $M$4/2))/2) / $M$4} -> 26554.545 | J36: =Table3[[#This Row],[Moving Average on Months]] - 1.96*STDEV(OFFSET(Table3[[#This Row],[Combined Daily order]], -$M$4/2, 0, $M$4+1, 1)) -> 14732.761 | K36: =Table3[[#This Row],[Moving Average on Months]] + 1.96*STDEV(OFFSET(Table3[[#This Row],[Combined Daily order]], -$M$4/2, 0, $M$4+1, 1)) -> 38376.33 | L36: #N/A | N36: =$V$46 -> 45729.883 | O36: =$U$46 -> 5411.2257
B37: 45545.196 | C37: =INT(B37) -> 45545 | D37: 11210 | F37: =WORKDAY(F36,-1) -> 45517 | G37: =SUMIF(C:C, F37, D:D) -> 31923 | H37: =ROUNDUP(MONTH(Table3[[#This Row],[Date]])/3, 0) -> 3 | I37: {=(SUM(OFFSET(G37, -$M$4/2+1, 0, $M$4-1, 1)) + (INDIRECT("G" & ROW(G37) - $M$4/2) + INDIRECT("G" & ROW(G37) + $M$4/2))/2) / $M$4} -> 26246.864 | J37: =Table3[[#This Row],[Moving Average on Months]] - 1.96*STDEV(OFFSET(Table3[[#This Row],[Combined Daily order]], -$M$4/2, 0, $M$4+1, 1)) -> 14290.05 | K37: =Table3[[#This Row],[Moving Average on Months]] + 1.96*STDEV(OFFSET(Table3[[#This Row],[Combined Daily order]], -$M$4/2, 0, $M$4+1, 1)) -> 38203.677 | L37: #N/A | N37: =$V$46 -> 45729.883 | O37: =$U$46 -> 5411.2257
B38: 45544.797 | C38: =INT(B38) -> 45544 | D38: 13133 | F38: =WORKDAY(F37,-1) -> 45516 | G38: =SUMIF(C:C, F38, D:D) -> 19960 | H38: =ROUNDUP(MONTH(Table3[[#This Row],[Date]])/3, 0) -> 3 | I38: {=(SUM(OFFSET(G38, -$M$4/2+1, 0, $M$4-1, 1)) + (INDIRECT("G" & ROW(G38) - $M$4/2) + INDIRECT("G" & ROW(G38) + $M$4/2))/2) / $M$4} -> 25870.068 | J38: =Table3[[#This Row],[Moving Average on Months]] - 1.96*STDEV(OFFSET(Table3[[#This Row],[Combined Daily order]], -$M$4/2, 0, $M$4+1, 1)) -> 14008.656 | K38: =Table3[[#This Row],[Moving Average on Months]] + 1.96*STDEV(OFFSET(Table3[[#This Row],[Combined Daily order]], -$M$4/2, 0, $M$4+1, 1)) -> 37731.48 | L38: #N/A | N38: =$V$46 -> 45729.883 | O38: =$U$46 -> 5411.2257
B39: 45544.421 | C39: =INT(B39) -> 45544 | D39: 13618 | F39: =WORKDAY(F38,-1) -> 45513 | G39: =SUMIF(C:C, F39, D:D) -> 33096 | H39: =ROUNDUP(MONTH(Table3[[#This Row],[Date]])/3, 0) -> 3 | I39: {=(SUM(OFFSET(G39, -$M$4/2+1, 0, $M$4-1, 1)) + (INDIRECT("G" & ROW(G39) - $M$4/2) + INDIRECT("G" & ROW(G39) + $M$4/2))/2) / $M$4} -> 25463.114 | J39: =Table3[[#This Row],[Moving Average on Months]] - 1.96*STDEV(OFFSET(Table3[[#This Row],[Combined Daily order]], -$M$4/2, 0, $M$4+1, 1)) -> 13875.993 | K39: =Table3[[#This Row],[Moving Average on Months]] + 1.96*STDEV(OFFSET(Table3[[#This Row],[Combined Daily order]], -$M$4/2, 0, $M$4+1, 1)) -> 37050.235 | L39: #N/A | N39: =$V$46 -> 45729.883 | O39: =$U$46 -> 5411.2257
... B42: 45541.132 | C42: =INT(B42) -> 45541 | D42: 11090 | F42: =WORKDAY(F41,-1) -> 45510 | G42: =SUMIF(C:C, F42, D:D) -> 28224 | H42: =ROUNDUP(MONTH(Table3[[#This Row],[Date]])/3, 0) -> 3 | I42: {=(SUM(OFFSET(G42, -$M$4/2+1, 0, $M$4-1, 1)) + (INDIRECT("G" & ROW(G42) - $M$4/2) + INDIRECT("G" & ROW(G42) + $M$4/2))/2) / $M$4} -> 24149.773 | J42: =Table3[[#This Row],[Moving Average on Months]] - 1.96*STDEV(OFFSET(Table3[[#This Row],[Combined Daily order]], -$M$4/2, 0, $M$4+1, 1)) -> 12362.005 | K42: =Table3[[#This Row],[Moving Average on Months]] + 1.96*STDEV(OFFSET(Table3[[#This Row],[Combined Daily order]], -$M$4/2, 0, $M$4+1, 1)) -> 35937.541 | L42: #N/A | N42: =$V$46 -> 45729.883 | O42: =$U$46 -> 5411.2257
B43: 45540.747 | C43: =INT(B43) -> 45540 | D43: 12739 | F43: =WORKDAY(F42,-1) -> 45509 | G43: =SUMIF(C:C, F43, D:D) -> 19855 | H43: =ROUNDUP(MONTH(Table3[[#This Row],[Date]])/3, 0) -> 3 | I43: {=(SUM(OFFSET(G43, -$M$4/2+1, 0, $M$4-1, 1)) + (INDIRECT("G" & ROW(G43) - $M$4/2) + INDIRECT("G" & ROW(G43) + $M$4/2))/2) / $M$4} -> 23651.409 | J43: =Table3[[#This Row],[Moving Average on Months]] - 1.96*STDEV(OFFSET(Table3[[#This Row],[Combined Daily order]], -$M$4/2, 0, $M$4+1, 1)) -> 11903.073 | K43: =Table3[[#This Row],[Moving Average on Months]] + 1.96*STDEV(OFFSET(Table3[[#This Row],[Combined Daily order]], -$M$4/2, 0, $M$4+1, 1)) -> 35399.745 | L43: #N/A | N43: =$V$46 -> 45729.883 | O43: =$U$46 -> 5411.2257 | Q43: Confidence Interval computed on the whole series of data
...

Sheet Raw Beige and outliers handling
A1: Beige QC Headphones: Raw Data and Outliers Handling
B3: Date | C3: Column1 | D3: Orders | F3: Unique Date | G3: Combined Daily Order | H3: Quarter | I3: Moving Average on Months | J3: Lower Bound Computed on Moving Average | K3: Upper Bound Computed on Moving Average | L3: Presumed Outliers | M3: Period of Moving Average | N3: Lower Bound Computed on the whole series of data | O3: Upper Bound Computed on the whole series of data | S3: Bose Quiet Confort Beige
B4: 45562.707 | C4: =INT(B4) -> 45562 | D4: 6388 | F4: 45562 | G4: =SUMIF(C:C, F4, D:D) -> 12033 | H4: =ROUNDUP(MONTH(Table3[[#This Row],[Date]])/3, 0) -> 3 | L4: #N/A | M4: 22 | N4: =$W$48 -> 2594.4026 | O4: =$X$48 -> 23487.587
B5: 45562.285 | C5: =INT(B5) -> 45562 | D5: 5645 | F5: =WORKDAY(F4,-1) -> 45561 | G5: =SUMIF(C:C, F5, D:D) -> 18563 | H5: =ROUNDUP(MONTH(Table3[[#This Row],[Date]])/3, 0) -> 3 | L5: #N/A | N5: =$W$48 -> 2594.4026 | O5: =$X$48 -> 23487.587
B6: 45561.902 | C6: =INT(B6) -> 45561 | D6: 6615 | F6: =WORKDAY(F5,-1) -> 45560 | G6: =SUMIF(C:C, F6, D:D) -> 12821 | H6: =ROUNDUP(MONTH(Table3[[#This Row],[Date]])/3, 0) -> 3 | L6: #N/A | N6: =$W$48 -> 2594.4026 | O6: =$X$48 -> 23487.587
B7: 45561.481 | C7: =INT(B7) -> 45561 | D7: 5755 | F7: =WORKDAY(F6,-1) -> 45559 | G7: =SUMIF(C:C, F7, D:D) -> 19276 | H7: =ROUNDUP(MONTH(Table3[[#This Row],[Date]])/3, 0) -> 3 | L7: #N/A | N7: =$W$48 -> 2594.4026 | O7: =$X$48 -> 23487.587
B8: 45561.098 | C8: =INT(B8) -> 45561 | D8: 6193 | F8: =WORKDAY(F7,-1) -> 45558 | G8: =SUMIF(C:C, F8, D:D) -> 12583 | H8: =ROUNDUP(MONTH(Table3[[#This Row],[Date]])/3, 0) -> 3 | L8: #N/A | N8: =$W$48 -> 2594.4026 | O8: =$X$48 -> 23487.587
B9: 45560.725 | C9: =INT(B9) -> 45560 | D9: 6732 | F9: =WORKDAY(F8,-1) -> 45555 | G9: =SUMIF(C:C, F9, D:D) -> 18787 | H9: =ROUNDUP(MONTH(Table3[[#This Row],[Date]])/3, 0) -> 3 | L9: #N/A | N9: =$W$48 -> 2594.4026 | O9: =$X$48 -> 23487.587
B10: 45560.306 | C10: =INT(B10) -> 45560 | D10: 6089 | F10: =WORKDAY(F9,-1) -> 45554 | G10: =SUMIF(C:C, F10, D:D) -> 11693 | H10: =ROUNDUP(MONTH(Table3[[#This Row],[Date]])/3, 0) -> 3 | L10: #N/A | N10: =$W$48 -> 2594.4026 | O10: =$X$48 -> 23487.587
B11: 45559.887 | C11: =INT(B11) -> 45559 | D11: 7041 | F11: =WORKDAY(F10,-1) -> 45553 | G11: =SUMIF(C:C, F11, D:D) -> 11473 | H11: =ROUNDUP(MONTH(Table3[[#This Row],[Date]])/3, 0) -> 3 | L11: #N/A | N11: =$W$48 -> 2594.4026 | O11: =$X$48 -> 23487.587
B12: 45559.459 | C12: =INT(B12) -> 45559 | D12: 6565 | F12: =WORKDAY(F11,-1) -> 45552 | G12: =SUMIF(C:C, F12, D:D) -> 18928 | H12: =ROUNDUP(MONTH(Table3[[#This Row],[Date]])/3, 0) -> 3 | L12: #N/A | N12: =$W$48 -> 2594.4026 | O12: =$X$48 -> 23487.587
B13: 45559.055 | C13: =INT(B13) -> 45559 | D13: 5670 | F13: =WORKDAY(F12,-1) -> 45551 | G13: =SUMIF(C:C, F13, D:D) -> 13779 | H13: =ROUNDUP(MONTH(Table3[[#This Row],[Date]])/3, 0) -> 3 | L13: #N/A | N13: =$W$48 -> 2594.4026 | O13: =$X$48 -> 23487.587
B14: 45558.654 | C14: =INT(B14) -> 45558 | D14: 6088 | F14: =WORKDAY(F13,-1) -> 45548 | G14: =SUMIF(C:C, F14, D:D) -> 18795 | H14: =ROUNDUP(MONTH(Table3[[#This Row],[Date]])/3, 0) -> 3 | L14: #N/A | N14: =$W$48 -> 2594.4026 | O14: =$X$48 -> 23487.587
B15: 45558.26 | C15: =INT(B15) -> 45558 | D15: 6495 | F15: =WORKDAY(F14,-1) -> 45547 | G15: =SUMIF(C:C, F15, D:D) -> 11667 | H15: =ROUNDUP(MONTH(Table3[[#This Row],[Date]])/3, 0) -> 3 | I15: {=(SUM(OFFSET(G15, -$M$4/2+1, 0, $M$4-1, 1)) + (INDIRECT("G" & ROW(G15) - $M$4/2) + INDIRECT("G" & ROW(G15) + $M$4/2))/2) / $M$4} -> 15034.182 | J15: =Table5[[#This Row],[Moving Average on Months]] - 1.96*STDEV(OFFSET(Table5[[#This Row],[Combined Daily Order]], -$M$4/2, 0, $M$4+1, 1)) -> 8619.1002 | K15: =Table5[[#This Row],[Moving Average on Months]] + 1.96*STDEV(OFFSET(Table5[[#This Row],[Combined Daily Order]], -$M$4/2, 0, $M$4+1, 1)) -> 21449.263 | L15: #N/A | N15: =$W$48 -> 2594.4026 | O15: =$X$48 -> 23487.587
B16: 45555.835 | C16: =INT(B16) -> 45555 | D16: 5677 | F16: =WORKDAY(F15,-1) -> 45546 | G16: =SUMIF(C:C, F16, D:D) -> 17317 | H16: =ROUNDUP(MONTH(Table3[[#This Row],[Date]])/3, 0) -> 3 | I16: {=(SUM(OFFSET(G16, -$M$4/2+1, 0, $M$4-1, 1)) + (INDIRECT("G" & ROW(G16) - $M$4/2) + INDIRECT("G" & ROW(G16) + $M$4/2))/2) / $M$4} -> 15029.614 | J16: =Table5[[#This Row],[Moving Average on Months]] - 1.96*STDEV(OFFSET(Table5[[#This Row],[Combined Daily Order]], -$M$4/2, 0, $M$4+1, 1)) -> 8602.2126 | K16: =Table5[[#This Row],[Moving Average on Months]] + 1.96*STDEV(OFFSET(Table5[[#This Row],[Combined Daily Order]], -$M$4/2, 0, $M$4+1, 1)) -> 21457.015 | L16: #N/A | N16: =$W$48 -> 2594.4026 | O16: =$X$48 -> 23487.587
B17: 45555.406 | C17: =INT(B17) -> 45555 | D17: 6584 | F17: =WORKDAY(F16,-1) -> 45545 | G17: =SUMIF(C:C, F17, D:D) -> 12128 | H17: =ROUNDUP(MONTH(Table3[[#This Row],[Date]])/3, 0) -> 3 | I17: {=(SUM(OFFSET(G17, -$M$4/2+1, 0, $M$4-1, 1)) + (INDIRECT("G" & ROW(G17) - $M$4/2) + INDIRECT("G" & ROW(G17) + $M$4/2))/2) / $M$4} -> 14970.409 | J17: =Table5[[#This Row],[Moving Average on Months]] - 1.96*STDEV(OFFSET(Table5[[#This Row],[Combined Daily Order]], -$M$4/2, 0, $M$4+1, 1)) -> 8667.9106 | K17: =Table5[[#This Row],[Moving Average on Months]] + 1.96*STDEV(OFFSET(Table5[[#This Row],[Combined Daily Order]], -$M$4/2, 0, $M$4+1, 1)) -> 21272.908 | L17: #N/A | N17: =$W$48 -> 2594.4026 | O17: =$X$48 -> 23487.587
B18: 45555.002 | C18: =INT(B18) -> 45555 | D18: 6526 | F18: =WORKDAY(F17,-1) -> 45544 | G18: =SUMIF(C:C, F18, D:D) -> 19007 | H18: =ROUNDUP(MONTH(Table3[[#This Row],[Date]])/3, 0) -> 3 | I18: {=(SUM(OFFSET(G18, -$M$4/2+1, 0, $M$4-1, 1)) + (INDIRECT("G" & ROW(G18) - $M$4/2) + INDIRECT("G" & ROW(G18) + $M$4/2))/2) / $M$4} -> 14901.886 | J18: =Table5[[#This Row],[Moving Average on Months]] - 1.96*STDEV(OFFSET(Table5[[#This Row],[Combined Daily Order]], -$M$4/2, 0, $M$4+1, 1)) -> 8556.6894 | K18: =Table5[[#This Row],[Moving Average on Months]] + 1.96*STDEV(OFFSET(Table5[[#This Row],[Combined Daily Order]], -$M$4/2, 0, $M$4+1, 1)) -> 21247.083 | L18: #N/A | N18: =$W$48 -> 2594.4026 | O18: =$X$48 -> 23487.587
B19: 45554.574 | C19: =INT(B19) -> 45554 | D19: 5713 | F19: =WORKDAY(F18,-1) -> 45541 | G19: =SUMIF(C:C, F19, D:D) -> 17738 | H19: =ROUNDUP(MONTH(Table3[[#This Row],[Date]])/3, 0) -> 3 | I19: {=(SUM(OFFSET(G19, -$M$4/2+1, 0, $M$4-1, 1)) + (INDIRECT("G" & ROW(G19) - $M$4/2) + INDIRECT("G" & ROW(G19) + $M$4/2))/2) / $M$4} -> 14829 | J19: =Table5[[#This Row],[Moving Average on Months]] - 1.96*STDEV(OFFSET(Table5[[#This Row],[Combined Daily Order]], -$M$4/2, 0, $M$4+1, 1)) -> 8719.8644 | K19: =Table5[[#This Row],[Moving Average on Months]] + 1.96*STDEV(OFFSET(Table5[[#This Row],[Combined Daily Order]], -$M$4/2, 0, $M$4+1, 1)) -> 20938.136 | L19: #N/A | N19: =$W$48 -> 2594.4026 | O19: =$X$48 -> 23487.587
B20: 45554.185 | C20: =INT(B20) -> 45554 | D20: 5980 | F20: =WORKDAY(F19,-1) -> 45540 | G20: =SUMIF(C:C, F20, D:D) -> 10845 | H20: =ROUNDUP(MONTH(Table3[[#This Row],[Date]])/3, 0) -> 3 | I20: {=(SUM(OFFSET(G20, -$M$4/2+1, 0, $M$4-1, 1)) + (INDIRECT("G" & ROW(G20) - $M$4/2) + INDIRECT("G" & ROW(G20) + $M$4/2))/2) / $M$4} -> 14744.477 | J20: =Table5[[#This Row],[Moving Average on Months]] - 1.96*STDEV(OFFSET(Table5[[#This Row],[Combined Daily Order]], -$M$4/2, 0, $M$4+1, 1)) -> 8520.7879 | K20: =Table5[[#This Row],[Moving Average on Months]] + 1.96*STDEV(OFFSET(Table5[[#This Row],[Combined Daily Order]], -$M$4/2, 0, $M$4+1, 1)) -> 20968.167 | L20: #N/A | N20: =$W$48 -> 2594.4026 | O20: =$X$48 -> 23487.587
B21: 45553.763 | C21: =INT(B21) -> 45553 | D21: 5914 | F21: =WORKDAY(F20,-1) -> 45539 | G21: =SUMIF(C:C, F21, D:D) -> 17695 | H21: =ROUNDUP(MONTH(Table3[[#This Row],[Date]])/3, 0) -> 3 | I21: {=(SUM(OFFSET(G21, -$M$4/2+1, 0, $M$4-1, 1)) + (INDIRECT("G" & ROW(G21) - $M$4/2) + INDIRECT("G" & ROW(G21) + $M$4/2))/2) / $M$4} -> 14690.841 | J21: =Table5[[#This Row],[Moving Average on Months]] - 1.96*STDEV(OFFSET(Table5[[#This Row],[Combined Daily Order]], -$M$4/2, 0, $M$4+1, 1)) -> 8633.0348 | K21: =Table5[[#This Row],[Moving Average on Months]] + 1.96*STDEV(OFFSET(Table5[[#This Row],[Combined Daily Order]], -$M$4/2, 0, $M$4+1, 1)) -> 20748.647 | L21: #N/A | N21: =$W$48 -> 2594.4026 | O21: =$X$48 -> 23487.587
B22: 45553.377 | C22: =INT(B22) -> 45553 | D22: 5559 | F22: =WORKDAY(F21,-1) -> 45538 | G22: =SUMIF(C:C, F22, D:D) -> 12392 | H22: =ROUNDUP(MONTH(Table3[[#This Row],[Date]])/3, 0) -> 3 | I22: {=(SUM(OFFSET(G22, -$M$4/2+1, 0, $M$4-1, 1)) + (INDIRECT("G" & ROW(G22) - $M$4/2) + INDIRECT("G" & ROW(G22) + $M$4/2))/2) / $M$4} -> 14815.75 | J22: =Table5[[#This Row],[Moving Average on Months]] - 1.96*STDEV(OFFSET(Table5[[#This Row],[Combined Daily Order]], -$M$4/2, 0, $M$4+1, 1)) -> 8761.1056 | K22: =Table5[[#This Row],[Moving Average on Months]] + 1.96*STDEV(OFFSET(Table5[[#This Row],[Combined Daily Order]], -$M$4/2, 0, $M$4+1, 1)) -> 20870.394 | L22: #N/A | N22: =$W$48 -> 2594.4026 | O22: =$X$48 -> 23487.587
B23: 45552.971 | C23: =INT(B23) -> 45552 | D23: 5925 | F23: =WORKDAY(F22,-1) -> 45537 | G23: =SUMIF(C:C, F23, D:D) -> 16595 | H23: =ROUNDUP(MONTH(Table3[[#This Row],[Date]])/3, 0) -> 3 | I23: {=(SUM(OFFSET(G23, -$M$4/2+1, 0, $M$4-1, 1)) + (INDIRECT("G" & ROW(G23) - $M$4/2) + INDIRECT("G" & ROW(G23) + $M$4/2))/2) / $M$4} -> 14775.159 | J23: =Table5[[#This Row],[Moving Average on Months]] - 1.96*STDEV(OFFSET(Table5[[#This Row],[Combined Daily Order]], -$M$4/2, 0, $M$4+1, 1)) -> 8817.2245 | K23: =Table5[[#This Row],[Moving Average on Months]] + 1.96*STDEV(OFFSET(Table5[[#This Row],[Combined Daily Order]], -$M$4/2, 0, $M$4+1, 1)) -> 20733.094 | L23: #N/A | N23: =$W$48 -> 2594.4026 | O23: =$X$48 -> 23487.587
B24: 45552.58 | C24: =INT(B24) -> 45552 | D24: 6163 | F24: =WORKDAY(F23,-1) -> 45534 | G24: =SUMIF(C:C, F24, D:D) -> 11528 | H24: =ROUNDUP(MONTH(Table3[[#This Row],[Date]])/3, 0) -> 3 | I24: {=(SUM(OFFSET(G24, -$M$4/2+1, 0, $M$4-1, 1)) + (INDIRECT("G" & ROW(G24) - $M$4/2) + INDIRECT("G" & ROW(G24) + $M$4/2))/2) / $M$4} -> 14648.5 | J24: =Table5[[#This Row],[Moving Average on Months]] - 1.96*STDEV(OFFSET(Table5[[#This Row],[Combined Daily Order]], -$M$4/2, 0, $M$4+1, 1)) -> 8656.544 | K24: =Table5[[#This Row],[Moving Average on Months]] + 1.96*STDEV(OFFSET(Table5[[#This Row],[Combined Daily Order]], -$M$4/2, 0, $M$4+1, 1)) -> 20640.456 | L24: #N/A | N24: =$W$48 -> 2594.4026 | O24: =$X$48 -> 23487.587
B25: 45552.169 | C25: =INT(B25) -> 45552 | D25: 6840 | F25: =WORKDAY(F24,-1) -> 45533 | G25: =SUMIF(C:C, F25, D:D) -> 11871 | H25: =ROUNDUP(MONTH(Table3[[#This Row],[Date]])/3, 0) -> 3 | I25: {=(SUM(OFFSET(G25, -$M$4/2+1, 0, $M$4-1, 1)) + (INDIRECT("G" & ROW(G25) - $M$4/2) + INDIRECT("G" & ROW(G25) + $M$4/2))/2) / $M$4} -> 14500.386 | J25: =Table5[[#This Row],[Moving Average on Months]] - 1.96*STDEV(OFFSET(Table5[[#This Row],[Combined Daily Order]], -$M$4/2, 0, $M$4+1, 1)) -> 8495.7054 | K25: =Table5[[#This Row],[Moving Average on Months]] + 1.96*STDEV(OFFSET(Table5[[#This Row],[Combined Daily Order]], -$M$4/2, 0, $M$4+1, 1)) -> 20505.067 | L25: #N/A | N25: =$W$48 -> 2594.4026 | O25: =$X$48 -> 23487.587
B26: 45551.762 | C26: =INT(B26) -> 45551 | D26: 6787 | F26: =WORKDAY(F25,-1) -> 45532 | G26: =SUMIF(C:C, F26, D:D) -> 18509 | H26: =ROUNDUP(MONTH(Table3[[#This Row],[Date]])/3, 0) -> 3 | I26: {=(SUM(OFFSET(G26, -$M$4/2+1, 0, $M$4-1, 1)) + (INDIRECT("G" & ROW(G26) - $M$4/2) + INDIRECT("G" & ROW(G26) + $M$4/2))/2) / $M$4} -> 14487.318 | J26: =Table5[[#This Row],[Moving Average on Months]] - 1.96*STDEV(OFFSET(Table5[[#This Row],[Combined Daily Order]], -$M$4/2, 0, $M$4+1, 1)) -> 8751.6121 | K26: =Table5[[#This Row],[Moving Average on Months]] + 1.96*STDEV(OFFSET(Table5[[#This Row],[Combined Daily Order]], -$M$4/2, 0, $M$4+1, 1)) -> 20223.024 | L26: #N/A | N26: =$W$48 -> 2594.4026 | O26: =$X$48 -> 23487.587
... B40: 45544.139 | C40: =INT(B40) -> 45544 | D40: 5806 | F40: =WORKDAY(F39,-1) -> 45512 | G40: =SUMIF(C:C, F40, D:D) -> 9372 | H40: =ROUNDUP(MONTH(Table3[[#This Row],[Date]])/3, 0) -> 3 | I40: {=(SUM(OFFSET(G40, -$M$4/2+1, 0, $M$4-1, 1)) + (INDIRECT("G" & ROW(G40) - $M$4/2) + INDIRECT("G" & ROW(G40) + $M$4/2))/2) / $M$4} -> 12254.795 | J40: =Table5[[#This Row],[Moving Average on Months]] - 1.96*STDEV(OFFSET(Table5[[#This Row],[Combined Daily Order]], -$M$4/2, 0, $M$4+1, 1)) -> 6783.0432 | K40: =Table5[[#This Row],[Moving Average on Months]] + 1.96*STDEV(OFFSET(Table5[[#This Row],[Combined Daily Order]], -$M$4/2, 0, $M$4+1, 1)) -> 17726.548 | L40: #N/A | N40: =$W$48 -> 2594.4026 | O40: =$X$48 -> 23487.587
B41: 45541.845 | C41: =INT(B41) -> 45541 | D41: 6184 | F41: =WORKDAY(F40,-1) -> 45511 | G41: =SUMIF(C:C, F41, D:D) -> 9242 | H41: =ROUNDUP(MONTH(Table3[[#This Row],[Date]])/3, 0) -> 3 | I41: {=(SUM(OFFSET(G41, -$M$4/2+1, 0, $M$4-1, 1)) + (INDIRECT("G" & ROW(G41) - $M$4/2) + INDIRECT("G" & ROW(G41) + $M$4/2))/2) / $M$4} -> 12073.136 | J41: =Table5[[#This Row],[Moving Average on Months]] - 1.96*STDEV(OFFSET(Table5[[#This Row],[Combined Daily Order]], -$M$4/2, 0, $M$4+1, 1)) -> 6395.0157 | K41: =Table5[[#This Row],[Moving Average on Months]] + 1.96*STDEV(OFFSET(Table5[[#This Row],[Combined Daily Order]], -$M$4/2, 0, $M$4+1, 1)) -> 17751.257 | L41: #N/A | N41: =$W$48 -> 2594.4026 | O41: =$X$48 -> 23487.587 | S41: Confidence Interval computed on the whole series of data
B42: 45541.456 | C42: =INT(B42) -> 45541 | D42: 5410 | F42: =WORKDAY(F41,-1) -> 45510 | G42: =SUMIF(C:C, F42, D:D) -> 14792 | H42: =ROUNDUP(MONTH(Table3[[#This Row],[Date]])/3, 0) -> 3 | I42: {=(SUM(OFFSET(G42, -$M$4/2+1, 0, $M$4-1, 1)) + (INDIRECT("G" & ROW(G42) - $M$4/2) + INDIRECT("G" & ROW(G42) + $M$4/2))/2) / $M$4} -> 11904.159 | J42: =Table5[[#This Row],[Moving Average on Months]] - 1.96*STDEV(OFFSET(Table5[[#This Row],[Combined Daily Order]], -$M$4/2, 0, $M$4+1, 1)) -> 6541.2482 | K42: =Table5[[#This Row],[Moving Average on Months]] + 1.96*STDEV(OFFSET(Table5[[#This Row],[Combined Daily Order]], -$M$4/2, 0, $M$4+1, 1)) -> 17267.07 | L42: #N/A | N42: =$W$48 -> 2594.4026 | O42: =$X$48 -> 23487.587
B43: 45541.055 | C43: =INT(B43) -> 45541 | D43: 6144 | F43: =WORKDAY(F42,-1) -> 45509 | G43: =SUMIF(C:C, F43, D:D) -> 8842 | H43: =ROUNDUP(MONTH(Table3[[#This Row],[Date]])/3, 0) -> 3 | I43: {=(SUM(OFFSET(G43, -$M$4/2+1, 0, $M$4-1, 1)) + (INDIRECT("G" & ROW(G43) - $M$4/2) + INDIRECT("G" & ROW(G43) + $M$4/2))/2) / $M$4} -> 11704.455 | J43: =Table5[[#This Row],[Moving Average on Months]] - 1.96*STDEV(OFFSET(Table5[[#This Row],[Combined Daily Order]], -$M$4/2, 0, $M$4+1, 1)) -> 6074.2096 | K43: =Table5[[#This Row],[Moving Average on Months]] + 1.96*STDEV(OFFSET(Table5[[#This Row],[Combined Daily Order]], -$M$4/2, 0, $M$4+1, 1)) -> 17334.7 | L43: #N/A | N43: =$W$48 -> 2594.4026 | O43: =$X$48 -> 23487.587
B44: 45540.667 | C44: =INT(B44) -> 45540 | D44: 5343 | F44: =WORKDAY(F43,-1) -> 45506 | G44: =SUMIF(C:C, F44, D:D) -> 13816 | H44: =ROUNDUP(MONTH(Table3[[#This Row],[Date]])/3, 0) -> 3 | I44: {=(SUM(OFFSET(G44, -$M$4/2+1, 0, $M$4-1, 1)) + (INDIRECT("G" & ROW(G44) - $M$4/2) + INDIRECT("G" & ROW(G44) + $M$4/2))/2) / $M$4} -> 11472.25 | J44: =Table5[[#This Row],[Moving Average on Months]] - 1.96*STDEV(OFFSET(Table5[[#This Row],[Combined Daily Order]], -$M$4/2, 0, $M$4+1, 1)) -> 6291.2053 | K44: =Table5[[#This Row],[Moving Average on Months]] + 1.96*STDEV(OFFSET(Table5[[#This Row],[Combined Daily Order]], -$M$4/2, 0, $M$4+1, 1)) -> 16653.295 | L44: #N/A | N44: =$W$48 -> 2594.4026 | O44: =$X$48 -> 23487.587
B45: 45540.285 | C45: =INT(B45) -> 45540 | D45: 5502 | F45: =WORKDAY(F44,-1) -> 45505 | G45: =SUMIF(C:C, F45, D:D) -> 8437 | H45: =ROUNDUP(MONTH(Table3[[#This Row],[Date]])/3, 0) -> 3 | I45: {=(SUM(OFFSET(G45, -$M$4/2+1, 0, $M$4-1, 1)) + (INDIRECT("G" & ROW(G45) - $M$4/2) + INDIRECT("G" & ROW(G45) + $M$4/2))/2) / $M$4} -> 11217.568 | J45: =Table5[[#This Row],[Moving Average on Months]] - 1.96*STDEV(OFFSET(Table5[[#This Row],[Combined Daily Order]], -$M$4/2, 0, $M$4+1, 1)) -> 5674.5696 | K45: =Table5[[#This Row],[Moving Average on Months]] + 1.96*STDEV(OFFSET(Table5[[#This Row],[Combined Daily Order]], -$M$4/2, 0, $M$4+1, 1)) -> 16760.567 | L45: #N/A | N45: =$W$48 -> 2594.4026 | O45: =$X$48 -> 23487.587 | S45: Confidence Interval computed on the whole series of data
B46: 45539.862 | C46: =INT(B46) -> 45539 | D46: 6189 | F46: =WORKDAY(F45,-1) -> 45504 | G46: =SUMIF(C:C, F46, D:D) -> 12711 | H46: =ROUNDUP(MONTH(Table3[[#This Row],[Date]])/3, 0) -> 3 | I46: {=(SUM(OFFSET(G46, -$M$4/2+1, 0, $M$4-1, 1)) + (INDIRECT("G" & ROW(G46) - $M$4/2) + INDIRECT("G" & ROW(G46) + $M$4/2))/2) / $M$4} -> 10981.932 | J46: =Table5[[#This Row],[Moving Average on Months]] - 1.96*STDEV(OFFSET(Table5[[#This Row],[Combined Daily Order]], -$M$4/2, 0, $M$4+1, 1)) -> 5979.2071 | K46: =Table5[[#This Row],[Moving Average on Months]] + 1.96*STDEV(OFFSET(Table5[[#This Row],[Combined Daily Order]], -$M$4/2, 0, $M$4+1, 1)) -> 15984.657 | L46: #N/A | N46: =$W$48 -> 2594.4026 | O46: =$X$48 -> 23487.587
B47: 45539.455 | C47: =INT(B47) -> 45539 | D47: 5253 | F47: =WORKDAY(F46,-1) -> 45503 | G47: =SUMIF(C:C, F47, D:D) -> 8729 | H47: =ROUNDUP(MONTH(Table3[[#This Row],[Date]])/3, 0) -> 3 | I47: {=(SUM(OFFSET(G47, -$M$4/2+1, 0, $M$4-1, 1)) + (INDIRECT("G" & ROW(G47) - $M$4/2) + INDIRECT("G" & ROW(G47) + $M$4/2))/2) / $M$4} -> 10790.568 | J47: =Table5[[#This Row],[Moving Average on Months]] - 1.96*STDEV(OFFSET(Table5[[#This Row],[Combined Daily Order]], -$M$4/2, 0, $M$4+1, 1)) -> 5597.4494 | K47: =Table5[[#This Row],[Moving Average on Months]] + 1.96*STDEV(OFFSET(Table5[[#This Row],[Combined Daily Order]], -$M$4/2, 0, $M$4+1, 1)) -> 15983.687 | L47: #N/A | N47: =$W$48 -> 2594.4026 | O47: =$X$48 -> 23487.587 | S47: Average | T47: Standard Deviation | U47: Confidence Level | V47: Z-Score | W47: CI1 | X47: CI2
B48: 45539.063 | C48: =INT(B48) -> 45539 | D48: 6253 | F48: =WORKDAY(F47,-1) -> 45502 | G48: =SUMIF(C:C, F48, D:D) -> 12264 | H48: =ROUNDUP(MONTH(Table3[[#This Row],[Date]])/3, 0) -> 3 | I48: {=(SUM(OFFSET(G48, -$M$4/2+1, 0, $M$4-1, 1)) + (INDIRECT("G" & ROW(G48) - $M$4/2) + INDIRECT("G" & ROW(G48) + $M$4/2))/2) / $M$4} -> 10520.068 | J48: =Table5[[#This Row],[Moving Average on Months]] - 1.96*STDEV(OFFSET(Table5[[#This Row],[Combined Daily Order]], -$M$4/2, 0, $M$4+1, 1)) -> 5782.6677 | K48: =Table5[[#This Row],[Moving Average on Months]] + 1.96*STDEV(OFFSET(Table5[[#This Row],[Combined Daily Order]], -$M$4/2, 0, $M$4+1, 1)) -> 15257.469 | L48: #N/A | N48: =$W$48 -> 2594.4026 | O48: =$X$48 -> 23487.587 | S48: =AVERAGE(G4:G806) -> 13040.995 | T48: =STDEV(G4:G806) -> 5329.8941 | U48: 0.95 | V48: 1.96 | W48: =S48-V48*T48 -> 2594.4026 | X48: =S48+V48*T48 -> 23487.587
B49: 45538.65 | C49: =INT(B49) -> 45538 | D49: 5735 | F49: =WORKDAY(F48,-1) -> 45499 | G49: =SUMIF(C:C, F49, D:D) -> 12629 | H49: =ROUNDUP(MONTH(Table3[[#This Row],[Date]])/3, 0) -> 3 | I49: {=(SUM(OFFSET(G49, -$M$4/2+1, 0, $M$4-1, 1)) + (INDIRECT("G" & ROW(G49) - $M$4/2) + INDIRECT("G" & ROW(G49) + $M$4/2))/2) / $M$4} -> 10348.432 | J49: =Table5[[#This Row],[Moving Average on Months]] - 1.96*STDEV(OFFSET(Table5[[#This Row],[Combined Daily Order]], -$M$4/2, 0, $M$4+1, 1)) -> 5555.8947 | K49: =Table5[[#This Row],[Moving Average on Months]] + 1.96*STDEV(OFFSET(Table5[[#This Row],[Combined Daily Order]], -$M$4/2, 0, $M$4+1, 1)) -> 15140.969 | L49: #N/A | N49: =$W$48 -> 2594.4026 | O49: =$X$48 -> 23487.587
B50: 45538.266 | C50: =INT(B50) -> 45538 | D50: 6657 | F50: =WORKDAY(F49,-1) -> 45498 | G50: =SUMIF(C:C, F50, D:D) -> 8391 | H50: =ROUNDUP(MONTH(Table3[[#This Row],[Date]])/3, 0) -> 3 | I50: {=(SUM(OFFSET(G50, -$M$4/2+1, 0, $M$4-1, 1)) + (INDIRECT("G" & ROW(G50) - $M$4/2) + INDIRECT("G" & ROW(G50) + $M$4/2))/2) / $M$4} -> 10193.682 | J50: =Table5[[#This Row],[Moving Average on Months]] - 1.96*STDEV(OFFSET(Table5[[#This Row],[Combined Daily Order]], -$M$4/2, 0, $M$4+1, 1)) -> 5365.4695 | K50: =Table5[[#This Row],[Moving Average on Months]] + 1.96*STDEV(OFFSET(Table5[[#This Row],[Combined Daily Order]], -$M$4/2, 0, $M$4+1, 1)) -> 15021.894 | L50: #N/A | N50: =$W$48 -> 2594.4026 | O50: =$X$48 -> 23487.587
B51: 45537.84 | C51: =INT(B51) -> 45537 | D51: 5179 | F51: =WORKDAY(F50,-1) -> 45497 | G51: =SUMIF(C:C, F51, D:D) -> 12118 | H51: =ROUNDUP(MONTH(Table3[[#This Row],[Date]])/3, 0) -> 3 | I51: {=(SUM(OFFSET(G51, -$M$4/2+1, 0, $M$4-1, 1)) + (INDIRECT("G" & ROW(G51) - $M$4/2) + INDIRECT("G" & ROW(G51) + $M$4/2))/2) / $M$4} -> 10069.114 | J51: =Table5[[#This Row],[Moving Average on Months]] - 1.96*STDEV(OFFSET(Table5[[#This Row],[Combined Daily Order]], -$M$4/2, 0, $M$4+1, 1)) -> 5380.0386 | K51: =Table5[[#This Row],[Moving Average on Months]] + 1.96*STDEV(OFFSET(Table5[[#This Row],[Combined Daily Order]], -$M$4/2, 0, $M$4+1, 1)) -> 14758.189 | L51: #N/A | N51: =$W$48 -> 2594.4026 | O51: =$X$48 -> 23487.587
B52: 45537.453 | C52: =INT(B52) -> 45537 | D52: 5174 | F52: =WORKDAY(F51,-1) -> 45496 | G52: =SUMIF(C:C, F52, D:D) -> 8541 | H52: =ROUNDUP(MONTH(Table3[[#This Row],[Date]])/3, 0) -> 3 | I52: {=(SUM(OFFSET(G52, -$M$4/2+1, 0, $M$4-1, 1)) + (INDIRECT("G" & ROW(G52) - $M$4/2) + INDIRECT("G" & ROW(G52) + $M$4/2))/2) / $M$4} -> 10057.568 | J52: =Table5[[#This Row],[Moving Average on Months]] - 1.96*STDEV(OFFSET(Table5[[#This Row],[Combined Daily Order]], -$M$4/2, 0, $M$4+1, 1)) -> 5342.7648 | K52: =Table5[[#This Row],[Moving Average on Months]] + 1.96*STDEV(OFFSET(Table5[[#This Row],[Combined Daily Order]], -$M$4/2, 0, $M$4+1, 1)) -> 14772.372 | L52: #N/A | N52: =$W$48 -> 2594.4026 | O52: =$X$48 -> 23487.587 | S52: Confidence Interval computed on each year
B53: 45537.066 | C53: =INT(B53) -> 45537 | D53: 6242 | F53: =WORKDAY(F52,-1) -> 45495 | G53: =SUMIF(C:C, F53, D:D) -> 11675 | H53: =ROUNDUP(MONTH(Table3[[#This Row],[Date]])/3, 0) -> 3 | I53: {=(SUM(OFFSET(G53, -$M$4/2+1, 0, $M$4-1, 1)) + (INDIRECT("G" & ROW(G53) - $M$4/2) + INDIRECT("G" & ROW(G53) + $M$4/2))/2) / $M$4} -> 9938.2727 | J53: =Table5[[#This Row],[Moving Average on Months]] - 1.96*STDEV(OFFSET(Table5[[#This Row],[Combined Daily Order]], -$M$4/2, 0, $M$4+1, 1)) -> 5109.7042 | K53: =Table5[[#This Row],[Moving Average on Months]] + 1.96*STDEV(OFFSET(Table5[[#This Row],[Combined Daily Order]], -$M$4/2, 0, $M$4+1, 1)) -> 14766.841 | L53: #N/A | N53: =$W$48 -> 2594.4026 | O53: =$X$48 -> 23487.587
B54: 45534.578 | C54: =INT(B54) -> 45534 | D54: 6175 | F54: =WORKDAY(F53,-1) -> 45492 | G54: =SUMIF(C:C, F54, D:D) -> 7658 | H54: =ROUNDUP(MONTH(Table3[[#This Row],[Date]])/3, 0) -> 3 | I54: {=(SUM(OFFSET(G54, -$M$4/2+1, 0, $M$4-1, 1)) + (INDIRECT("G" & ROW(G54) - $M$4/2) + INDIRECT("G" & ROW(G54) + $M$4/2))/2) / $M$4} -> 9824 | J54: =Table5[[#This Row],[Moving Average on Months]] - 1.96*STDEV(OFFSET(Table5[[#This Row],[Combined Daily Order]], -$M$4/2, 0, $M$4+1, 1)) -> 5414.7998 | K54: =Table5[[#This Row],[Moving Average on Months]] + 1.96*STDEV(OFFSET(Table5[[#This Row],[Combined Daily Order]], -$M$4/2, 0, $M$4+1, 1)) -> 14233.2 | L54: #N/A | N54: =$W$48 -> 2594.4026 | O54: =$X$48 -> 23487.587 | S54: Year 2021 | U54: Year 2022 | W54: Year 2023 | Y54: Year 2024
...

Sheet Clean Data
A1: Clean Data
B3: Date | C3: Orders BLACK | D3: Orders BEIGE | E3: Orders TOTAL | F3: Graphs:
B4: 45562 | C4: =Table3[[#This Row],[Combined Daily order]] -> 25910 | D4: =Table5[[#This Row],[Combined Daily Order]] -> 12033 | E4: =C4+D4 -> 37943
B5: 45561 | C5: =Table3[[#This Row],[Combined Daily order]] -> 36491 | D5: =Table5[[#This Row],[Combined Daily Order]] -> 18563 | E5: =C5+D5 -> 55054
B6: 45560 | C6: =Table3[[#This Row],[Combined Daily order]] -> 26068 | D6: =Table5[[#This Row],[Combined Daily Order]] -> 12821 | E6: =C6+D6 -> 38889
B7: 45559 | C7: =Table3[[#This Row],[Combined Daily order]] -> 40865 | D7: =Table5[[#This Row],[Combined Daily Order]] -> 19276 | E7: =C7+D7 -> 60141
B8: 45558 | C8: =Table3[[#This Row],[Combined Daily order]] -> 27032 | D8: =Table5[[#This Row],[Combined Daily Order]] -> 12583 | E8: =C8+D8 -> 39615
B9: 45555 | C9: =Table3[[#This Row],[Combined Daily order]] -> 25465 | D9: =Table5[[#This Row],[Combined Daily Order]] -> 18787 | E9: =C9+D9 -> 44252
B10: 45554 | C10: =Table3[[#This Row],[Combined Daily order]] -> 36114 | D10: =Table5[[#This Row],[Combined Daily Order]] -> 11693 | E10: =C10+D10 -> 47807
B11: 45553 | C11: =Table3[[#This Row],[Combined Daily order]] -> 25049 | D11: =Table5[[#This Row],[Combined Daily Order]] -> 11473 | E11: =C11+D11 -> 36522
B12: 45552 | C12: =Table3[[#This Row],[Combined Daily order]] -> 36767 | D12: =Table5[[#This Row],[Combined Daily Order]] -> 18928 | E12: =C12+D12 -> 55695
B13: 45551 | C13: =Table3[[#This Row],[Combined Daily order]] -> 27301 | D13: =Table5[[#This Row],[Combined Daily Order]] -> 13779 | E13: =C13+D13 -> 41080
B14: 45548 | C14: =Table3[[#This Row],[Combined Daily order]] -> 35320 | D14: =Table5[[#This Row],[Combined Daily Order]] -> 18795 | E14: =C14+D14 -> 54115
B15: 45547 | C15: =Table3[[#This Row],[Combined Daily order]] -> 25240 | D15: =Table5[[#This Row],[Combined Daily Order]] -> 11667 | E15: =C15+D15 -> 36907
... B381: 45035 | C381: =Table3[[#This Row],[Combined Daily order]] -> 17195 | D381: =Table5[[#This Row],[Combined Daily Order]] -> 12759 | E381: =C381+D381 -> 29954
B382: 45034 | C382: =Table3[[#This Row],[Combined Daily order]] -> 24913 | D382: =AVERAGE(D383,D381) -> 13237 | E382: =C382+D382 -> 38150
B383: 45033 | C383: =Table3[[#This Row],[Combined Daily order]] -> 18956 | D383: =Table5[[#This Row],[Combined Daily Order]] -> 13715 | E383: =C383+D383 -> 32671
B384: 45030 | C384: =Table3[[#This Row],[Combined Daily order]] -> 25647 | D384: =Table5[[#This Row],[Combined Daily Order]] -> 8264 | E384: =C384+D384 -> 33911
B385: 45029 | C385: =Table3[[#This Row],[Combined Daily order]] -> 18341 | D385: =Table5[[#This Row],[Combined Daily Order]] -> 8391 | E385: =C385+D385 -> 26732
B386: 45028 | C386: =Table3[[#This Row],[Combined Daily order]] -> 28519 | D386: =Table5[[#This Row],[Combined Daily Order]] -> 12803 | E386: =C386+D386 -> 41322
B387: 45027 | C387: =Table3[[#This Row],[Combined Daily order]] -> 19879 | D387: =Table5[[#This Row],[Combined Daily Order]] -> 9795 | E387: =C387+D387 -> 29674
B388: 45026 | C388: =Table3[[#This Row],[Combined Daily order]] -> 27733 | D388: =Table5[[#This Row],[Combined Daily Order]] -> 13783 | E388: =C388+D388 -> 41516
B389: 45023 | C389: =Table3[[#This Row],[Combined Daily order]] -> 20034 | D389: =Table5[[#This Row],[Combined Daily Order]] -> 13237 | E389: =C389+D389 -> 33271
B390: 45022 | C390: =Table3[[#This Row],[Combined Daily order]] -> 28303 | D390: =Table5[[#This Row],[Combined Daily Order]] -> 9698 | E390: =C390+D390 -> 38001
B391: 45021 | C391: =Table3[[#This Row],[Combined Daily order]] -> 18037 | D391: =Table5[[#This Row],[Combined Daily Order]] -> 8536 | E391: =C391+D391 -> 26573
B392: 45020 | C392: =Table3[[#This Row],[Combined Daily order]] -> 26882 | D392: =Table5[[#This Row],[Combined Daily Order]] -> 12896 | E392: =C392+D392 -> 39778
B393: 45019 | C393: =Table3[[#This Row],[Combined Daily order]] -> 17677 | D393: =Table5[[#This Row],[Combined Daily Order]] -> 12616 | E393: =C393+D393 -> 30293
B394: 45016 | C394: =Table3[[#This Row],[Combined Daily order]] -> 27964 | D394: =Table5[[#This Row],[Combined Daily Order]] -> 14343 | E394: =C394+D394 -> 42307
... B806: 44440 | C806: =Table3[[#This Row],[Combined Daily order]] -> 30157 | D806: =Table5[[#This Row],[Combined Daily Order]] -> 9514 | E806: =C806+D806 -> 39671

Sheet Aggregated Data
A1: Aggregated Data
B3: Period | C3: Sum of Orders BLACK | D3: Sum of Orders BEIGE | E3: Sum of Orders TOTAL | AF3: Weekly reference period (for verification only)
B4: 2021 | C4: 2931305 | D4: 1413099 | E4: 4344404
B5: Trim.3 | C5: 548044 | D5: 264407 | E5: 812451 | AG5: Week starting on: | AH5: Orders BLACK | AI5: Orders BEIGE | AJ5: Orders TOTAL
B6: sep | C6: 548044 | D6: 264407 | E6: 812451 | AG6: 45558 | AH6: =SUM(OFFSET('Clean Data'!$C$4,(ROW()-ROW($AH$6))*5,0,5,1)) -> 156366 | AI6: =SUM(OFFSET('Clean Data'!$D$4,(ROW()-ROW($AI$6))*5,0,5,1)) -> 75276 | AJ6: =AH6+AI6 -> 231642
B7: Trim.4 | C7: 2383261 | D7: 1148692 | E7: 3531953 | AG7: =AG6-7 -> 45551 | AH7: =SUM(OFFSET('Clean Data'!$C$4,(ROW()-ROW($AH$6))*5,0,5,1)) -> 150696 | AI7: =SUM(OFFSET('Clean Data'!$D$4,(ROW()-ROW($AI$6))*5,0,5,1)) -> 74660 | AJ7: =AH7+AI7 -> 225356
B8: oct | C8: 558742 | D8: 289780 | E8: 848522 | AG8: =AG7-7 -> 45544 | AH8: =SUM(OFFSET('Clean Data'!$C$4,(ROW()-ROW($AH$6))*5,0,5,1)) -> 150598 | AI8: =SUM(OFFSET('Clean Data'!$D$4,(ROW()-ROW($AI$6))*5,0,5,1)) -> 78914 | AJ8: =AH8+AI8 -> 229512
B9: nov | C9: 834836 | D9: 377003 | E9: 1211839 | AG9: =AG8-7 -> 45537 | AH9: =SUM(OFFSET('Clean Data'!$C$4,(ROW()-ROW($AH$6))*5,0,5,1)) -> 169056 | AI9: =SUM(OFFSET('Clean Data'!$D$4,(ROW()-ROW($AI$6))*5,0,5,1)) -> 75265 | AJ9: =AH9+AI9 -> 244321
B10: dic | C10: 989683 | D10: 481909 | E10: 1471592 | AG10: =AG9-7 -> 45530 | AH10: =SUM(OFFSET('Clean Data'!$C$4,(ROW()-ROW($AH$6))*5,0,5,1)) -> 141681 | AI10: =SUM(OFFSET('Clean Data'!$D$4,(ROW()-ROW($AI$6))*5,0,5,1)) -> 70687 | AJ10: =AH10+AI10 -> 212368
B11: 2022 | C11: 6056804 | D11: 3244943 | E11: 9301747 | AG11: =AG10-7 -> 45523 | AH11: =SUM(OFFSET('Clean Data'!$C$4,(ROW()-ROW($AH$6))*5,0,5,1)) -> 148019 | AI11: =SUM(OFFSET('Clean Data'!$D$4,(ROW()-ROW($AI$6))*5,0,5,1)) -> 68502 | AJ11: =AH11+AI11 -> 216521
B12: Trim.1 | C12: 1242158 | D12: 631293 | E12: 1873451 | AG12: =AG11-7 -> 45516 | AH12: =SUM(OFFSET('Clean Data'!$C$4,(ROW()-ROW($AH$6))*5,0,5,1)) -> 127391 | AI12: =SUM(OFFSET('Clean Data'!$D$4,(ROW()-ROW($AI$6))*5,0,5,1)) -> 67375 | AJ12: =AH12+AI12 -> 194766
B13: ene | C13: 407349 | D13: 222237 | E13: 629586 | AG13: =AG12-7 -> 45509 | AH13: =SUM(OFFSET('Clean Data'!$C$4,(ROW()-ROW($AH$6))*5,0,5,1)) -> 131167 | AI13: =SUM(OFFSET('Clean Data'!$D$4,(ROW()-ROW($AI$6))*5,0,5,1)) -> 56787 | AJ13: =AH13+AI13 -> 187954
B14: feb | C14: 379315 | D14: 179556 | E14: 558871 | AG14: =AG13-7 -> 45502 | AH14: =SUM(OFFSET('Clean Data'!$C$4,(ROW()-ROW($AH$6))*5,0,5,1)) -> 107660 | AI14: =SUM(OFFSET('Clean Data'!$D$4,(ROW()-ROW($AI$6))*5,0,5,1)) -> 55957 | AJ14: =AH14+AI14 -> 163617
B15: mar | C15: 455494 | D15: 229500 | E15: 684994 | AG15: =AG14-7 -> 45495 | AH15: =SUM(OFFSET('Clean Data'!$C$4,(ROW()-ROW($AH$6))*5,0,5,1)) -> 103065 | AI15: =SUM(OFFSET('Clean Data'!$D$4,(ROW()-ROW($AI$6))*5,0,5,1)) -> 53354 | AJ15: =AH15+AI15 -> 156419
B16: Trim.2 | C16: 1196816 | D16: 600826 | E16: 1797642 | AG16: =AG15-7 -> 45488 | AH16: =SUM(OFFSET('Clean Data'!$C$4,(ROW()-ROW($AH$6))*5,0,5,1)) -> 84386 | AI16: =SUM(OFFSET('Clean Data'!$D$4,(ROW()-ROW($AI$6))*5,0,5,1)) -> 42704 | AJ16: =AH16+AI16 -> 127090
B17: abr | C17: 404221 | D17: 206568 | E17: 610789 | AG17: =AG16-7 -> 45481 | AH17: =SUM(OFFSET('Clean Data'!$C$4,(ROW()-ROW($AH$6))*5,0,5,1)) -> 93659 | AI17: =SUM(OFFSET('Clean Data'!$D$4,(ROW()-ROW($AI$6))*5,0,5,1)) -> 46682 | AJ17: =AH17+AI17 -> 140341
B18: may | C18: 427348 | D18: 218681 | E18: 646029 | AG18: =AG17-7 -> 45474 | AH18: =SUM(OFFSET('Clean Data'!$C$4,(ROW()-ROW($AH$6))*5,0,5,1)) -> 97505 | AI18: =SUM(OFFSET('Clean Data'!$D$4,(ROW()-ROW($AI$6))*5,0,5,1)) -> 44582 | AJ18: =AH18+AI18 -> 142087
... B58: Grand Total | C58: 20533155 | D58: 10446651 | E58: 30979806 | AG58: =AG57-7 -> 45194 | AH58: =SUM(OFFSET('Clean Data'!$C$4,(ROW()-ROW($AH$6))*5,0,5,1)) -> 144992 | AI58: =SUM(OFFSET('Clean Data'!$D$4,(ROW()-ROW($AI$6))*5,0,5,1)) -> 68314 | AJ58: =AH58+AI58 -> 213306
AG59: =AG58-7 -> 45187 | AH59: =SUM(OFFSET('Clean Data'!$C$4,(ROW()-ROW($AH$6))*5,0,5,1)) -> 156704 | AI59: =SUM(OFFSET('Clean Data'!$D$4,(ROW()-ROW($AI$6))*5,0,5,1)) -> 70447 | AJ59: =AH59+AI59 -> 227151
AG60: =AG59-7 -> 45180 | AH60: =SUM(OFFSET('Clean Data'!$C$4,(ROW()-ROW($AH$6))*5,0,5,1)) -> 147098 | AI60: =SUM(OFFSET('Clean Data'!$D$4,(ROW()-ROW($AI$6))*5,0,5,1)) -> 74473 | AJ60: =AH60+AI60 -> 221571
AG61: =AG60-7 -> 45173 | AH61: =SUM(OFFSET('Clean Data'!$C$4,(ROW()-ROW($AH$6))*5,0,5,1)) -> 147083 | AI61: =SUM(OFFSET('Clean Data'!$D$4,(ROW()-ROW($AI$6))*5,0,5,1)) -> 69316 | AJ61: =AH61+AI61 -> 216399
AG62: =AG61-7 -> 45166 | AH62: =SUM(OFFSET('Clean Data'!$C$4,(ROW()-ROW($AH$6))*5,0,5,1)) -> 131815 | AI62: =SUM(OFFSET('Clean Data'!$D$4,(ROW()-ROW($AI$6))*5,0,5,1)) -> 71130 | AJ62: =AH62+AI62 -> 202945
AG63: =AG62-7 -> 45159 | AH63: =SUM(OFFSET('Clean Data'!$C$4,(ROW()-ROW($AH$6))*5,0,5,1)) -> 140983 | AI63: =SUM(OFFSET('Clean Data'!$D$4,(ROW()-ROW($AI$6))*5,0,5,1)) -> 62713 | AJ63: =AH63+AI63 -> 203696
AG64: =AG63-7 -> 45152 | AH64: =SUM(OFFSET('Clean Data'!$C$4,(ROW()-ROW($AH$6))*5,0,5,1)) -> 136549 | AI64: =SUM(OFFSET('Clean Data'!$D$4,(ROW()-ROW($AI$6))*5,0,5,1)) -> 60028 | AJ64: =AH64+AI64 -> 196577
AG65: =AG64-7 -> 45145 | AH65: =SUM(OFFSET('Clean Data'!$C$4,(ROW()-ROW($AH$6))*5,0,5,1)) -> 111316 | AI65: =SUM(OFFSET('Clean Data'!$D$4,(ROW()-ROW($AI$6))*5,0,5,1)) -> 53899 | AJ65: =AH65+AI65 -> 165215
AG66: =AG65-7 -> 45138 | AH66: =SUM(OFFSET('Clean Data'!$C$4,(ROW()-ROW($AH$6))*5,0,5,1)) -> 109676 | AI66: =SUM(OFFSET('Clean Data'!$D$4,(ROW()-ROW($AI$6))*5,0,5,1)) -> 53889 | AJ66: =AH66+AI66 -> 163565
AG67: =AG66-7 -> 45131 | AH67: =SUM(OFFSET('Clean Data'!$C$4,(ROW()-ROW($AH$6))*5,0,5,1)) -> 94002 | AI67: =SUM(OFFSET('Clean Data'!$D$4,(ROW()-ROW($AI$6))*5,0,5,1)) -> 47730 | AJ67: =AH67+AI67 -> 141732
AG68: =AG67-7 -> 45124 | AH68: =SUM(OFFSET('Clean Data'!$C$4,(ROW()-ROW($AH$6))*5,0,5,1)) -> 80604 | AI68: =SUM(OFFSET('Clean Data'!$D$4,(ROW()-ROW($AI$6))*5,0,5,1)) -> 42794 | AJ68: =AH68+AI68 -> 123398
AG69: =AG68-7 -> 45117 | AH69: =SUM(OFFSET('Clean Data'!$C$4,(ROW()-ROW($AH$6))*5,0,5,1)) -> 77034 | AI69: =SUM(OFFSET('Clean Data'!$D$4,(ROW()-ROW($AI$6))*5,0,5,1)) -> 44914 | AJ69: =AH69+AI69 -> 121948
AG70: =AG69-7 -> 45110 | AH70: =SUM(OFFSET('Clean Data'!$C$4,(ROW()-ROW($AH$6))*5,0,5,1)) -> 73435 | AI70: =SUM(OFFSET('Clean Data'!$D$4,(ROW()-ROW($AI$6))*5,0,5,1)) -> 42054 | AJ70: =AH70+AI70 -> 115489
... AG166: =AG165-7 -> 44438 | AH166: =SUM(OFFSET('Clean Data'!$C$4,(ROW()-ROW($AH$6))*5,0,5,1)) -> 80706 | AI166: =SUM(OFFSET('Clean Data'!$D$4,(ROW()-ROW($AI$6))*5,0,5,1)) -> 32428 | AJ166: =AH166+AI166 -> 113134

Sheet Autocorrelation
A1: Autocorrelation Analysis
B4: Month | C4: Orders | D4: Mean | E4: Dev | F4: Dev_squared | H4: Lag | I4: Numerator | J4: Denominator | K4: ACF
B5: 44440 | C5: =GETPIVOTDATA("Sum of Orders TOTAL",'Aggregated Data'!$B$3,"Meses (Date)",9,"Trimestres (Date)",3,"Años (Date)",2021) -> 812451 | D5: =AVERAGE(C5:C41) -> 837292.05 | E5: =C5-$D$5 -> -24841.054 | F5: =E5^2 -> 6.1707797e+08 | H5: 0 | I5: {=SUMPRODUCT((E5:E41) * (E5:E41))} -> 2.7882752e+12 | J5: =SUM(F5:F41) -> 2.7882752e+12 | K5: =I5/$J$5 -> 1
B6: oct | C6: =GETPIVOTDATA("Sum of Orders TOTAL",'Aggregated Data'!B3,"Meses (Date)",10,"Trimestres (Date)",4,"Años (Date)",2021) -> 848522 | E6: =C6-$D$5 -> 11229.946 | F6: =E6^2 -> 1.2611169e+08 | H6: 1 | I6: {=SUMPRODUCT((E5:E40) * (E6:E41))} -> 1.3909457e+12 | K6: =I6/$J$5 -> 0.49885524
B7: nov | C7: =GETPIVOTDATA("Sum of Orders TOTAL",'Aggregated Data'!$B$3,"Meses (Date)",11,"Trimestres (Date)",4,"Años (Date)",2021) -> 1211839 | E7: =C7-$D$5 -> 374546.95 | F7: =E7^2 -> 1.4028541e+11 | H7: 2 | I7: {=SUMPRODUCT((E5:E39) * (E7:E41))} -> -3.7774504e+10 | K7: =I7/$J$5 -> -0.013547624
B8: dic | C8: =GETPIVOTDATA("Sum of Orders TOTAL",'Aggregated Data'!$B$3,"Meses (Date)",12,"Trimestres (Date)",4,"Años (Date)",2021) -> 1471592 | E8: =C8-$D$5 -> 634299.95 | F8: =E8^2 -> 4.0233642e+11 | H8: 3 | I8: {=SUMPRODUCT((E5:E38) * (E8:E41))} -> -2.5692208e+11 | K8: =I8/$J$5 -> -0.092143732
B9: 44562 | C9: =GETPIVOTDATA("Sum of Orders TOTAL",'Aggregated Data'!$B$3,"Meses (Date)",1,"Trimestres (Date)",1,"Años (Date)",2022) -> 629586 | E9: =C9-$D$5 -> -207706.05 | F9: =E9^2 -> 4.3141805e+10 | H9: 4 | I9: {=SUMPRODUCT((E5:E37) * (E9:E41))} -> -5.44664e+11 | K9: =I9/$J$5 -> -0.19534084
B10: feb | C10: =GETPIVOTDATA("Sum of Orders TOTAL",'Aggregated Data'!$B$3,"Meses (Date)",2,"Trimestres (Date)",1,"Años (Date)",2022) -> 558871 | E10: =C10-$D$5 -> -278421.05 | F10: =E10^2 -> 7.7518283e+10 | H10: 5 | I10: {=SUMPRODUCT((E5:E36) * (E10:E41))} -> -7.6844047e+11 | K10: =I10/$J$5 -> -0.27559707
B11: mar | C11: =GETPIVOTDATA("Sum of Orders TOTAL",'Aggregated Data'!$B$3,"Meses (Date)",3,"Trimestres (Date)",1,"Años (Date)",2022) -> 684994 | E11: =C11-$D$5 -> -152298.05 | F11: =E11^2 -> 2.3194697e+10 | H11: 6 | I11: {=SUMPRODUCT((E5:E35) * (E11:E41))} -> -9.0357942e+11 | K11: =I11/$J$5 -> -0.32406394
B12: abr | C12: =GETPIVOTDATA("Sum of Orders TOTAL",'Aggregated Data'!$B$3,"Meses (Date)",4,"Trimestres (Date)",2,"Años (Date)",2022) -> 610789 | E12: =C12-$D$5 -> -226503.05 | F12: =E12^2 -> 5.1303633e+10 | H12: 7 | I12: {=SUMPRODUCT((E5:E34) * (E12:E41))} -> -1.0096025e+12 | K12: =I12/$J$5 -> -0.36208854
